Model pACE_B8_N4_18_07_lap.1.1, Test bulk_Si_diamond
Test run at 2020-09-03 14:17

model file: ../../models/pACE_B8_N4_18_07_lap.1.1/model.py
============================================================
Traceback (most recent call last):
  File "../../../scripts/run-model-test.py", line 108, in <module>
    sys.stdout.write(open(model_file).read())
FileNotFoundError: [Errno 2] No such file or directory: '../../models/pACE_B8_N4_18_07_lap.1.1/model.py'
